## Promise输出题
### 1.Promise如果没有resolve或者reject，那么状态就是pending
```javascript
const promise1 = new Promise((resolve, reject) => {
  console.log('promise1')
})
console.log('1', promise1);

// 'promise1'
// '1' Promise{<pending>}

```



### 2.Promise.then只有在Promise状态改变后，才会执行
```javascript
const promise = new Promise((resolve, reject) => {
  console.log(1);
  console.log(2);
});
promise.then(() => {
  console.log(3);
});
console.log(4);
// 输出
// 1 2 4

```



### 3.Promise的状态一经改变就不能改变。
```javascript
const promise = new Promise((resolve, reject) => {
  resolve("success1");
  reject("error");
  resolve("success2");
});
promise
.then(res => {
    console.log("then: ", res);
  }).catch(err => {
    console.log("catch: ", err);
  })
// 输出 "then: success1"
```

具体过程解析：

+ 调用了第一个resolve，Promise的状态就变成了fullfilled
+ **<font style="color:#7E45E8;">因为状态不能再改变了，所以后面的reject和resolve都不会执行。</font>****<font style="color:#7E45E8;background-color:#FBDE28;">但是不影响代码的继续执行，不要以为这里就直接return了。</font>**

### 4.then和catch都会返回一个Promise。
这里如果没有返回值的话，可以默认理解返回`undefined`

```javascript
const promise = new Promise((resolve, reject) => {
  reject("error");
  resolve("success2");
});
promise
.then(res => {
    console.log("then1: ", res);
  }).then(res => {
    console.log("then2: ", res);
  }).catch(err => {
    console.log("catch: ", err);
  }).then(res => {
    console.log("then3: ", res);
  })
// catch:error
// then3:undefined
```

### 5.在then函数里面return，相当于Promise.resolve
> 当没有任何返回值的时候，可以理解为then返回Promise.resolve(undefined)
>

```javascript
Promise.resolve(1)
  .then(res => {
    console.log(res);
    return 2;
  })
  .catch(err => {
    return 3;
  })
  .then(res => {
    console.log(res);
  });

// 输出1，2
```

```javascript
Promise.reject(1)
  .then(res => {
    console.log(res);
    return 2;
  })
  .catch(err => {
    console.log(err);
    return 3
  })
  .then(res => {
    console.log(res);
  });
// 输出1，3
```

具体过程：

+ 先走到catch中去，然后return 3.相当于return Promise.resolve(3)。
+ 然后走进then中进行接受。

### 6.返回任何一个非Promise对象，都会被包装成Promise对象
```javascript
Promise.resolve().then(() => {
  return new Error('error!!!')
}).then(res => {
  console.log("then: ", res)
}).catch(err => {
  console.log("catch: ", err)
})
// 输出："then: " "Error: error!!!"
```

**<font style="background-color:#FBF5CB;">大家很震惊为什么走不到Promise.catch()里面去</font>**，因为return 的话，相当于等价于return Promise.resolve(new Error('error!!!'))

如果想要抛出错误，有两种方式

```javascript
return Promise.reject(new Error('error!!!'));

throw new Error('error!!!');
```

### 7.then或者catch返回值不能是Promise本身，否则会造成死循环
```javascript
const promise = Promise.resolve().then(() => {
  return promise;
})
promise.catch(console.err)
// 死循环
```

### 8.值穿透
```javascript
Promise.resolve(1)
  .then(2)
  .then(Promise.resolve(3))
  .then(console.log)

// 最后打印1
```

<font style="color:rgb(37, 41, 51);">第一个</font><font style="color:rgb(255, 80, 44);background-color:rgb(255, 245, 245);">then</font><font style="color:rgb(37, 41, 51);">和第二个</font><font style="color:rgb(255, 80, 44);background-color:rgb(255, 245, 245);">then</font><font style="color:rgb(37, 41, 51);">中传入的都不是函数，一个是数字类型，一个是对象类型，因此发生了透传，将</font><font style="color:rgb(255, 80, 44);background-color:rgb(255, 245, 245);">resolve(1)</font><font style="color:rgb(37, 41, 51);"> 的值直接传到最后一个</font><font style="color:rgb(255, 80, 44);background-color:rgb(255, 245, 245);">then</font><font style="color:rgb(37, 41, 51);">里。</font>

### 9.then函数的两个参数
```javascript
Promise.reject('err!!!')
  .then((res) => {
    console.log('success', res)
  }, (err) => {
    console.log('error', err)
  }).catch(err => {
    console.log('catch', err)
  })

// 'error' 'error!!!'
```

<font style="color:rgb(37, 41, 51);">它进入的是</font><font style="color:rgb(255, 80, 44);background-color:rgb(255, 245, 245);">then()</font><font style="color:rgb(37, 41, 51);">中的第二个参数里面，而如果把第二个参数去掉，就进入了</font><font style="color:rgb(255, 80, 44);background-color:rgb(255, 245, 245);">catch()</font><font style="color:rgb(37, 41, 51);">中：</font>

### 10.finally
+ 不管Promise对象最终的状态如何都会执行
+ 最终返回的对象是上一次的Promise对象值，<font style="color:#262626;background-color:#FBF5CB;">不管返回什么都没有效果(只是起到一个传递值的作用)</font><font style="color:#262626;">，</font>**<font style="color:#117CEE;">除非抛出一个错误，才会被catch函数接受。</font>**
+ finally最终回调里面没有任何参数

经典:

```javascript
Promise.resolve('1')
  .then(res => {
    console.log(res)
  })
  .finally(() => {
    console.log('finally')
  })
Promise.resolve('2')
  .finally(() => {
    console.log('finally2')
  	return '我是finally2返回的值'
  })
  .then(res => {
    console.log('finally2后面的then函数', res)
  })
// 1 
// finally2
// finaaly
// finally2后面的then函数 2
```

为什么finally要在finally2后面执行呢？

:::color3
可以这样理解，在Promise.resolve('1').then这个微任务还没有执行完，.finally是不会放到微任务队列当中，只有任务执行完了，才能放到微任务队列当中。

:::

### 11.链式调用后面的内容需要等待前一个调用执行完才会去执行
```javascript
function promise1 () {
  let p = new Promise((resolve) => {
    console.log('promise1');
    resolve('1')
  })
  return p;
}
function promise2 () {
  return new Promise((resolve, reject) => {
    reject('error')
  })
}
promise1()
  .then(res => console.log(res))
  .catch(err => console.log(err))
  .finally(() => console.log('finally1'))

promise2()
  .then(res => console.log(res))
  .catch(err => console.log(err))
  .finally(() => console.log('finally2'))

// promise1
// 1
// error
// finally1
// finally2

```

<font style="color:rgb(37, 41, 51);">就像是这里的</font><font style="color:rgb(255, 80, 44);background-color:rgb(255, 245, 245);">finally()</font><font style="color:rgb(37, 41, 51);">会等</font><font style="color:rgb(255, 80, 44);background-color:rgb(255, 245, 245);">promise1().then()</font><font style="color:rgb(37, 41, 51);">执行完才会将</font><font style="color:rgb(255, 80, 44);background-color:rgb(255, 245, 245);">finally()</font><font style="color:rgb(37, 41, 51);">加入微任务队列，其实如果这道题中你把</font><font style="color:rgb(255, 80, 44);background-color:rgb(255, 245, 245);">finally()</font><font style="color:rgb(37, 41, 51);">换成是</font><font style="color:rgb(255, 80, 44);background-color:rgb(255, 245, 245);">then()</font><font style="color:rgb(37, 41, 51);">也是这样的:</font>

```javascript
function promise1 () {
  let p = new Promise((resolve) => {
    console.log('promise1');
    resolve('1')
  })
  return p;
}
function promise2 () {
  return new Promise((resolve, reject) => {
    reject('error')
  })
}
promise1()
  .then(res => console.log(res))
  .catch(err => console.log(err))
  .then(() => console.log('finally1'))

promise2()
  .then(res => console.log(res))
  .catch(err => console.log(err))
  .then(() => console.log('finally2'))

```

### 12.关于async/await
```javascript
async function async1() {
  console.log("async1 start");
  await async2();
  console.log("async1 end");
}
async function async2() {
  console.log("async2");
}
async1();
console.log('start')

```

这个题输出什么？

:::color2
初学者可能会觉得是

:::

:::success
async1 start

async2

async1 end

start

:::

:::color3
<font style="color:#DF2A3F;">但实际上</font>

:::

:::success
async1 start

async2

start

async1 end

:::

这是为什么呢？

可以这样理解，**<font style="color:#ED740C;background-color:#FBF5CB;">await的下一条语句甚至于之后的语句都会被放到微任务执行。</font>**

将await转换成Promise的代码

```javascript
async function async1() {
  console.log("async1 start");
  // 原来代码
  // await async2();
  // console.log("async1 end");
  
  // 转换后代码
  new Promise(resolve => {
    console.log("async2")
    resolve()
  }).then(res => console.log("async1 end"))
}
async function async2() {
  console.log("async2");
}
async1();
console.log("start")

```



```javascript
async function async1() {
  console.log("async1 start");
  await async2();
  console.log("async1 end");
  setTimeout(() => {
    console.log('timer1')
  }, 0)
}
async function async2() {
  setTimeout(() => {
    console.log('timer2')
  }, 0)
  console.log("async2");
}
async1();
setTimeout(() => {
  console.log('timer3')
}, 0)
console.log("start")


// async1 start
// async2
// start
// async1 end
// timer2
// timer3
// timer1

```





### 13.async包裹的函数最终会返回一个Promise对象
```javascript
async function fn () {
  // return await 1234
  // 等同于
  return 123
}
fn().then(res => console.log(res))
// 123
```

### 14.await如果没有promise的返回结果就会一直卡着
```javascript
async function async1 () {
  console.log('async1 start');
  await new Promise(resolve => {
    console.log('promise1')
  }) // newPromise代码里面可以理解为同步代码，只有then函数才是微任务代码
  console.log('async1 success');
  return 'async1 end'
}
console.log('srcipt start')
async1().then(res => console.log(res))
console.log('srcipt end')

// script start
// async1 start
// promise1
// script end

```

### 15.await后面是一个异常和错误
```javascript
async function async1 () {
  await async2();
  console.log('async1');
  return 'async1 success'
}
async function async2 () {
  return new Promise((resolve, reject) => {
    console.log('async2')
    reject('error')
  })
}
async1().then(res => console.log(res))

```

**<font style="color:rgb(37, 41, 51);">如果在async函数中抛出了错误，则终止错误结果，不会继续向下执行。</font>**

**<font style="color:rgb(37, 41, 51);">这道题输出为</font>**

```javascript
'async2'
Uncaught (in promise) error
```

如果改为throw new Error也是一样的：

```javascript
async function async1 () {
  console.log('async1');
  throw new Error('error!!!')
  return 'async1 success'
}
async1().then(res => console.log(res))
```

结果为：

```javascript
'async1'
Uncaught (in promise) Error: error!!!
```



如果想要错误的地方不影响后序的执行，使用`try catch`进行异常捕获

```javascript
async function async1 () {
  try {
    await Promise.reject('error!!!')
  } catch(e) {
    console.log(e)
  }
  console.log('async1');
  return Promise.resolve('async1 success')
}
async1().then(res => console.log(res))
console.log('script start')
// 'script start'
// 'error!!!' // catch error是一个微任务。
// 'async1'
// 'async1 success'

```

### 16.resolve之后不会阻塞后续的同步代码运行
```javascript
async function async1() {
    console.log("async1 start")
    await async2()
    console.log("async1 end")
}
async function async2() {
    console.log("async2")
}
console.log("script start")
setTimeout(function () {
    console.log("settimeout")
})
async1()
new Promise(function (resolve) {
    console.log("promisel start")
    resolve()
    console.log("promise1 end")
}).then(function () {
    console.log("promisel then")
})
console.log("script end")
```

---

## 牛客
```javascript
function test() {
    setTimeout(() => {
        console.log(1)
    }, 0)
    new Promise((resolve) => {
        console.log(2)
        resolve()
        console.log(3)
        throw new Error()
    })
        .then(() => {
            console.log(4)
        })
        .catch(() => {
            console.log(5)
        })

    console.log(6)
}
// 2 3 6 4 1
test()
```



## 参考资料
[45道Promise题目](https://juejin.cn/post/6844904077537574919)

[听说你会Promise？ 那么如何控制请求并发数呢？ - 掘金](https://juejin.cn/post/7219961144584552504?searchId=2023110118011263DBB11E76771967292C)

